Issue while building the feature

Traceback (most recent call last):
  File "src/unicon/statemachine/statemachine.py", line 727, in unicon.statemachine.statemachine.StateMachine.go_to
  File "src/unicon/statemachine/statetransition.py", line 478, in unicon.statemachine.statetransition.AnyStateTransition.do_transitions
  File "src/unicon/eal/dialogs.py", line 459, in unicon.eal.dialogs.Dialog.process
  File "src/unicon/eal/dialog_processor.py", line 321, in unicon.eal.dialog_processor.SimpleDialogProcessor.process
  File "src/unicon/eal/dialog_processor.py", line 235, in unicon.eal.dialog_processor.SimpleDialogProcessor.expect_eval_statements
  File "/home/expert/venvs/main/lib/python3.9/site-packages/unicon/plugins/generic/statements.py", line 259, in password_handler
    credential = get_current_credential(context=context, session=session)
  File "/home/expert/venvs/main/lib/python3.9/site-packages/unicon/plugins/utils.py", line 80, in get_current_credential
    raise CredentialsExhaustedError(
unicon.core.errors.CredentialsExhaustedError: The following credentials have been tried without success : ['default']

The above exception was the direct cause of the following exception:

Traceback (most recent call last):
  File "src/unicon/bases/connection.py", line 757, in unicon.bases.connection.Connection.connect
  File "src/unicon/bases/routers/connection_provider.py", line 190, in unicon.bases.routers.connection_provider.BaseSingleRpConnectionProvider.connect
  File "src/unicon/bases/routers/connection_provider.py", line 217, in unicon.bases.routers.connection_provider.BaseSingleRpConnectionProvider.establish_connection
  File "src/unicon/statemachine/statemachine.py", line 730, in unicon.statemachine.statemachine.StateMachine.go_to
unicon.core.errors.StateMachineError: Failed while bringing device to "any" state

The above exception was the direct cause of the following exception:

Traceback (most recent call last):
  File "src/genie/cli/commands/learn.py", line 365, in genie.cli.commands.learn.LearnCommand._retrieve_ops
  File "/home/expert/venvs/main/lib/python3.9/site-packages/genie/libs/ops/ospf/iosxe/ospf.py", line 1017, in learn
    self.make(final_call=True)
  File "/home/expert/venvs/main/lib/python3.9/site-packages/genie/ops/base/base.py", line 101, in make
    self.maker.make(*args, **kwargs)
  File "src/genie/ops/base/maker.py", line 312, in genie.ops.base.maker.Maker.make
  File "src/genie/ops/base/maker.py", line 418, in genie.ops.base.maker.Maker._call_parser
  File "src/genie/metaparser/_metaparser.py", line 279, in genie.metaparser._metaparser.MetaParser.parse
  File "/home/expert/venvs/main/lib/python3.9/site-packages/genie/libs/parser/iosxe/show_ospf.py", line 344, in cli
    out = self.device.execute(self.cli_command)
  File "src/unicon/bases/routers/services.py", line 254, in unicon.bases.routers.services.BaseService.__call__
  File "src/unicon/bases/routers/services.py", line 155, in unicon.bases.routers.services.BaseService.pre_service
  File "src/unicon/bases/connection.py", line 763, in unicon.bases.connection.Connection.connect
unicon.core.errors.ConnectionError: failed to connect to R1
Failed while bringing device to "any" state
